{
  "xsize": 16,
  "zsize": 16,
  "refpalette": "nstf:test",
  "slices": [
    [
      "WWWWWWWWWWWWWWWW",
      "WWWWWWWWWWWWWWWW",
      "WWWWWWWWWWWWWWWW",
      "WWWWWWWWWWWWWWWW",
      "WWWWWWWWWWWWWWWW",
      "WWWWWWWWWWWWWWWW",
      "WWWWWWWWWWWWWWWW",
      "WWWWWWWWWWWWWWWW",
      "WWWWWWWWWWWWWWWW",
      "WWWWWWWWWWWWWWWW",
      "WWWWWWWWWWWWWWWW",
      "WWWWWWWWWWWWWWWW",
      "WWWWWWWWWWWWWWWW",
      "WWWWWWWWWWWWWWWW",
      "WWWWWWWWWWWWWWWW",
      "WWWWWWWWWWWWWWWW"
    ],
    [
      "WWWWWWWWWWWWWWWW",
      "WWWWWWWWWWWWWWWW",
      "WWWWWWWWWWWWWWWW",
      "WWWWWWWWWWWWWWWW",
      "WWWWWWWWWWWWWWWW",
      "WWWWWWWWWWWWWWWW",
      "WWWWWWWWWWWWWWWW",
      "WWWWWWWWWWWWWWWW",
      "WWWWWWWWWWWWWWWW",
      "WWWWWWWWWWWWWWWW",
      "WWWWWWWWWWWWWWWW",
      "WWWWWWWWWWWWWWWW",
      "WWWWWWWWWWWWWWWW",
      "WWWWWWWWWWWWWWWW",
      "WWWWWWWWWWWWWWWW",
      "WWWWWWWWWWWWWWWW"
    ],
    [
      "________________",
      "________________",
      "________________",
      "________________",
      "________________",
      "________________",
      "________________",
      "________________",
      "________________",
      "________________",
      "________________",
      "________________",
      "________________",
      "________________",
      "________________",
      "________________"
    ],
    [
      "________________",
      "________________",
      "________________",
      "________________",
      "________________",
      "________________",
      "________________",
      "________________",
      "________________",
      "________________",
      "________________",
      "________________",
      "________________",
      "________________",
      "________________",
      "________________"
    ],
    [
      "________________",
      "________________",
      "________________",
      "________________",
      "________________",
      "________________",
      "________________",
      "________________",
      "________________",
      "________________",
      "________________",
      "________________",
      "________________",
      "________________",
      "________________",
      "________________"
    ],
    [
      "________________",
      "________________",
      "________________",
      "________________",
      "________________",
      "________________",
      "________________",
      "________________",
      "________________",
      "________________",
      "________________",
      "________________",
      "________________",
      "________________",
      "________________",
      "________________"
    ]
  ]
}
