{
  "xsize": 16,
  "zsize": 16,
  "refpalette": "nstest:test",
  "slices": [
    [
      "GGGGGGGGGGGGGGGG",
      "GGGGGGGGGGGGGGGG",
      "GGGGGGGGGGGGGGGG",
      "GGGGGGGGGGGGGGGG",
      "GGGGGGGGGGGGGGGG",
      "GGGGGGGGGGGGGGGG",
      "GGGGGGGGGGGGGGGG",
      "GGGGGGGGGGGGGGGG",
      "GGGGGGGGGGGGGGGG",
      "GGGGGGGGGGGGGGGG",
      "GGGGGGGGGGGGGGGG",
      "GGGGGGGGGGGGGGGG",
      "GGGGGGGGGGGGGGGG",
      "GGGGGGGGGGGGGGGG",
      "GGGGGGGGGGGGGGGG",
      "GGGGGGGGGGGGGGGG"
    ],
    [
      "________________",
      "________________",
      "________________",
      "________________",
      "________________",
      "________________",
      "________________",
      "________________",
      "________________",
      "________________",
      "________________",
      "________________",
      "________________",
      "________________",
      "________________",
      "________________"
    ],
    [
      "________________",
      "________________",
      "________________",
      "________________",
      "________________",
      "________________",
      "________________",
      "________________",
      "________________",
      "________________",
      "________________",
      "________________",
      "________________",
      "________________",
      "________________",
      "________________"
    ],
    [
      "________________",
      "________________",
      "________________",
      "________________",
      "________________",
      "________________",
      "________________",
      "________________",
      "________________",
      "________________",
      "________________",
      "________________",
      "________________",
      "________________",
      "________________",
      "________________"
    ],
    [
      "________________",
      "________________",
      "________________",
      "________________",
      "________________",
      "________________",
      "________________",
      "________________",
      "________________",
      "________________",
      "________________",
      "________________",
      "________________",
      "________________",
      "________________",
      "________________"
    ],
    [
      "________________",
      "________________",
      "________________",
      "________________",
      "________________",
      "________________",
      "________________",
      "________________",
      "________________",
      "________________",
      "________________",
      "________________",
      "________________",
      "________________",
      "________________",
      "________________"
    ]
  ]
}
