{
  "xsize": 16,
  "zsize": 16,
  "refpalette": "nstest:test",
  "slices": [
    [
      "LLLLLLLLLLLLLLLL",
      "LLLLLLLLLLLLLLLL",
      "LLLLLLLLLLLLLLLL",
      "LLLLLLLLLLLLLLLL",
      "LLLLLLLLLLLLLLLL",
      "LLLLLLLLLLLLLLLL",
      "LLLLLLLLLLLLLLLL",
      "LLLLLLLLLLLLLLLL",
      "LLLLLLLLLLLLLLLL",
      "LLLLLLLLLLLLLLLL",
      "LLLLLLLLLLLLLLLL",
      "LLLLLLLLLLLLLLLL",
      "LLLLLLLLLLLLLLLL",
      "LLLLLLLLLLLLLLLL",
      "LLLLLLLLLLLLLLLL",
      "LLLLLLLLLLLLLLLL"
    ],
    [
      "________________",
      "________________",
      "________________",
      "________________",
      "________________",
      "________________",
      "________________",
      "________________",
      "________________",
      "________________",
      "________________",
      "________________",
      "________________",
      "________________",
      "________________",
      "________________"
    ],
    [
      "________________",
      "________________",
      "________________",
      "________________",
      "________________",
      "________________",
      "________________",
      "________________",
      "________________",
      "________________",
      "________________",
      "________________",
      "________________",
      "________________",
      "________________",
      "________________"
    ],
    [
      "________________",
      "________________",
      "________________",
      "________________",
      "________________",
      "________________",
      "________________",
      "________________",
      "________________",
      "________________",
      "________________",
      "________________",
      "________________",
      "________________",
      "________________",
      "________________"
    ],
    [
      "________________",
      "________________",
      "________________",
      "________________",
      "________________",
      "________________",
      "________________",
      "________________",
      "________________",
      "________________",
      "________________",
      "________________",
      "________________",
      "________________",
      "________________",
      "________________"
    ],
    [
      "________________",
      "________________",
      "________________",
      "________________",
      "________________",
      "________________",
      "________________",
      "________________",
      "________________",
      "________________",
      "________________",
      "________________",
      "________________",
      "________________",
      "________________",
      "________________"
    ]
  ]
}
