{
  "xsize": 16,
  "zsize": 16,
  "refpalette": "wt6:test",
  "slices": [
    [
      "################",
      "################",
      "################",
      "################",
      "################",
      "################",
      "################",
      "################",
      "################",
      "################",
      "################",
      "################",
      "################",
      "################",
      "################",
      "################"
    ],
    [
      "王王王王王王王王王王王王王王王王",
      "王______________王",
      "王______________王",
      "王______________王",
      "王______________王",
      "王______________王",
      "王______________王",
      "王______________王",
      "王______________王",
      "王______________王",
      "王______________王",
      "王______________王",
      "王______________王",
      "王______________王",
      "王______________王",
      "王王王王王王王王王王王王王王王王"
    ],
    [
      "王王王王王王王王王王王王王王王王",
      "王______________王",
      "王______________王",
      "王______________王",
      "王______________王",
      "王______________王",
      "王______________王",
      "王______________王",
      "王______________王",
      "王______________王",
      "王______________王",
      "王______________王",
      "王______________王",
      "王______________王",
      "王______________王",
      "王王王王王王王王王王王王王王王王"
    ],
    [
      "王王王王王王王王王王王王王王王王",
      "王______________王",
      "王______________王",
      "王______________王",
      "王______________王",
      "王______________王",
      "王______________王",
      "王______________王",
      "王______________王",
      "王______________王",
      "王______________王",
      "王______________王",
      "王______________王",
      "王______________王",
      "王______________王",
      "王王王王王王王王王王王王王王王王"
    ],
    [
      "王王王王王王王王王王王王王王王王",
      "王______________王",
      "王______________王",
      "王______________王",
      "王______________王",
      "王______________王",
      "王______________王",
      "王______________王",
      "王______________王",
      "王______________王",
      "王______________王",
      "王______________王",
      "王______________王",
      "王______________王",
      "王______________王",
      "王王王王王王王王王王王王王王王王"
    ],
    [
      "################",
      "################",
      "################",
      "################",
      "################",
      "################",
      "################",
      "################",
      "################",
      "################",
      "################",
      "################",
      "################",
      "################",
      "################",
      "################"
    ]
  ]
}
