{
  "xsize": 16,
  "zsize": 16,
  "refpalette": "wt6:test",
  "slices": [
    [
      "################",
      "################",
      "################",
      "################",
      "################",
      "################",
      "################",
      "################",
      "################",
      "################",
      "################",
      "################",
      "################",
      "################",
      "################",
      "################"
    ],
    [
      "################",
      "#______________#",
      "#______________#",
      "#______________#",
      "#______________#",
      "#______________#",
      "#______________#",
      "#______________#",
      "#___v___v___v__#",
      "#______________#",
      "#______________#",
      "#______________#",
      "#______________#",
      "#______________#",
      "#______________#",
      "################"
    ],
    [
      "################",
      "#______________#",
      "#______________#",
      "#______________#",
      "#______________#",
      "#______________#",
      "#______________#",
      "#______________#",
      "#______________#",
      "#______________#",
      "#______________#",
      "#______________#",
      "#______________#",
      "#______________#",
      "#______________#",
      "################"
    ],
    [
      "################",
      "#______________#",
      "#______________#",
      "#______________#",
      "#______________#",
      "#______________#",
      "#______________#",
      "#______________#",
      "#______________#",
      "#______________#",
      "#______________#",
      "#______________#",
      "#______________#",
      "#______________#",
      "#______________#",
      "################"
    ],
    [
      "################",
      "#______________#",
      "#______________#",
      "#______________#",
      "#______________#",
      "#______________#",
      "#______________#",
      "#______________#",
      "#______________#",
      "#______________#",
      "#______________#",
      "#______________#",
      "#______________#",
      "#______________#",
      "#______________#",
      "################"
    ],
    [
      "################",
      "################",
      "################",
      "################",
      "################",
      "################",
      "################",
      "################",
      "################",
      "################",
      "################",
      "################",
      "################",
      "################",
      "################",
      "################"
    ]
  ]
}
