{
  "xsize": 16,
  "zsize": 16,
  "refpalette": "wt6:test",
  "slices": [
    [
      "SSSSSSSSSSSSSSSS",
      "SSSSSSSSSSSSSSSS",
      "SSSSSSSSSSSSSSSS",
      "SSSSSSSSSSSSSSSS",
      "SSSSSSSSSSSSSSSS",
      "SSSSSSSSSSSSSSSS",
      "SSSSSSSSSSSSSSSS",
      "SSSSSSSSSSSSSSSS",
      "SSSSSSSSSSSSSSSS",
      "SSSSSSSSSSSSSSSS",
      "SSSSSSSSSSSSSSSS",
      "SSSSSSSSSSSSSSSS",
      "SSSSSSSSSSSSSSSS",
      "SSSSSSSSSSSSSSSS",
      "SSSSSSSSSSSSSSSS",
      "SSSSSSSSSSSSSSSS"
    ],
    [
      "################",
      "#______________#",
      "#______________#",
      "#______________#",
      "#______________#",
      "#_s__s__s__s_s_#",
      "#______________#",
      "#______________#",
      "#______________#",
      "#_____su_______#",
      "#______________#",
      "#______________#",
      "#______________#",
      "#______________#",
      "#______________#",
      "################"
    ],
    [
      "################",
      "#______________#",
      "#______________#",
      "#______________#",
      "#______________#",
      "#______________#",
      "#______________#",
      "#______________#",
      "#______________#",
      "#______________#",
      "#______________#",
      "#______________#",
      "#______________#",
      "#______________#",
      "#______________#",
      "################"
    ],
    [
      "################",
      "#______________#",
      "#______________#",
      "#______________#",
      "#______________#",
      "#______________#",
      "#______________#",
      "#______________#",
      "#______________#",
      "#______________#",
      "#______________#",
      "#______________#",
      "#______________#",
      "#______________#",
      "#______________#",
      "################"
    ],
    [
      "################",
      "#______________#",
      "#______________#",
      "#______________#",
      "#______________#",
      "#______________#",
      "#______________#",
      "#______________#",
      "#______________#",
      "#______________#",
      "#______________#",
      "#______________#",
      "#______________#",
      "#______________#",
      "#______________#",
      "################"
    ],
    [
      "SSSSSSSSSSSSSSSS",
      "SSSSSSSSSSSSSSSS",
      "SSSSSSSSSSSSSSSS",
      "SSSSSSSSSSSSSSSS",
      "SSSSSSSSSSSSSSSS",
      "SSSSSSSSSSSSSSSS",
      "SSSSSSSSSSSSSSSS",
      "SSSSSSSSSSSSSSSS",
      "SSSSSSSSSSSSSSSS",
      "SSSSSSSSSSSSSSSS",
      "SSSSSSSSSSSSSSSS",
      "SSSSSSSSSSSSSSSS",
      "SSSSSSSSSSSSSSSS",
      "SSSSSSSSSSSSSSSS",
      "SSSSSSSSSSSSSSSS",
      "SSSSSSSSSSSSSSSS"
    ]
  ]
}
