{
  "xsize": 16,
  "zsize": 16,
  "refpalette": "wtfail:test",
  "slices": [
    [
      "CCCCCCCCCCCCCCCC",
      "CCCCCCCCCCCCCCCC",
      "CCCCCCCCCCCCCCCC",
      "CCCCCCCCCCCCCCCC",
      "CCCCCCCCCCCCCCCC",
      "CCCCCCCCCCCCCCCC",
      "CCCCCCCCCCCCCCCC",
      "CCCCCCCCCCCCCCCC",
      "CCCCCCCCCCCCCCCC",
      "CCCCCCCCCCCCCCCC",
      "CCCCCCCCCCCCCCCC",
      "CCCCCCCCCCCCCCCC",
      "CCCCCCCCCCCCCCCC",
      "CCCCCCCCCCCCCCCC",
      "CCCCCCCCCCCCCCCC",
      "CCCCCCCCCCCCCCCC"
    ],
    [
      "CCCCCCCCCCCCCCCC",
      "C______________C",
      "C______________C",
      "C______________C",
      "C______________C",
      "C______________C",
      "C______________C",
      "C______________C",
      "C______________C",
      "C______________C",
      "C______________C",
      "C______________C",
      "C______________C",
      "C______________C",
      "C______________C",
      "CCCCCCCCCCCCCCCC"
    ],
    [
      "CCCCCCCCCCCCCCCC",
      "C______________C",
      "C______________C",
      "C______________C",
      "C______________C",
      "C______________C",
      "C______________C",
      "C______________C",
      "C______________C",
      "C______________C",
      "C______________C",
      "C______________C",
      "C______________C",
      "C______________C",
      "C______________C",
      "CCCCCCCCCCCCCCCC"
    ],
    [
      "CCCCCCCCCCCCCCCC",
      "C______________C",
      "C______________C",
      "C______________C",
      "C______________C",
      "C______________C",
      "C______________C",
      "C______________C",
      "C______________C",
      "C______________C",
      "C______________C",
      "C______________C",
      "C______________C",
      "C______________C",
      "C______________C",
      "CCCCCCCCCCCCCCCC"
    ],
    [
      "CCCCCCCCCCCCCCCC",
      "C______________C",
      "C______________C",
      "C______________C",
      "C______________C",
      "C______________C",
      "C______________C",
      "C______________C",
      "C______________C",
      "C______________C",
      "C______________C",
      "C______________C",
      "C______________C",
      "C______________C",
      "C______________C",
      "CCCCCCCCCCCCCCCC"
    ],
    [
      "CCCCCCCCCCCCCCCC",
      "CCCCCCCCCCCCCCCC",
      "CCCCCCCCCCCCCCCC",
      "CCCCCCCCCCCCCCCC",
      "CCCCCCCCCCCCCCCC",
      "CCCCCCCCCCCCCCCC",
      "CCCCCCCCCCCCCCCC",
      "CCCCCCCCCCCCCCCC",
      "CCCCCCCCCCCCCCCC",
      "CCCCCCCCCCCCCCCC",
      "CCCCCCCCCCCCCCCC",
      "CCCCCCCCCCCCCCCC",
      "CCCCCCCCCCCCCCCC",
      "CCCCCCCCCCCCCCCC",
      "CCCCCCCCCCCCCCCC",
      "CCCCCCCCCCCCCCCC"
    ]
  ]
}
