{
  "xsize": 16,
  "zsize": 16,
  "refpalette": "wt8:test",
  "slices": [
    [
      "xxxxxxxxxxxxxxxx",
      "xxxxxxxxxxxxxxxx",
      "xxxxxxxxxxxxxxxx",
      "xxxxxxxxxxxxxxxx",
      "xxxxxxxxxxxxxxxx",
      "xxxxxxxxxxxxxxxx",
      "xxxxxxxxxxxxxxxx",
      "xxxxxxxxxxxxxxxx",
      "xxxxxxxxxxxxxxxx",
      "xxxxxxxxxxxxxxxx",
      "xxxxxxxxxxxxxxxx",
      "xxxxxxxxxxxxxxxx",
      "xxxxxxxxxxxxxxxx",
      "xxxxxxxxxxxxxxxx",
      "xxxxxxxxxxxxxxxx",
      "xxxxxxxxxxxxxxxx"
    ],
    [
      "xxxxxxxxxxxxxxxx",
      "x______________x",
      "x______________x",
      "x______________x",
      "x______________x",
      "x______________x",
      "x______________x",
      "x______________x",
      "x______________x",
      "x______________x",
      "x______________x",
      "x______________x",
      "x______________x",
      "x______________x",
      "x______________x",
      "xxxxxxxxxxxxxxxx"
    ],
    [
      "xxxxxxxxxxxxxxxx",
      "x______________x",
      "x______________x",
      "x______________x",
      "x______________x",
      "x______________x",
      "x______________x",
      "x______________x",
      "x______________x",
      "x______________x",
      "x______________x",
      "x______________x",
      "x______________x",
      "x______________x",
      "x______________x",
      "xxxxxxxxxxxxxxxx"
    ],
    [
      "xxxxxxxxxxxxxxxx",
      "x______________x",
      "x______________x",
      "x______________x",
      "x______________x",
      "x______________x",
      "x______________x",
      "x______________x",
      "x______________x",
      "x______________x",
      "x______________x",
      "x______________x",
      "x______________x",
      "x______________x",
      "x______________x",
      "xxxxxxxxxxxxxxxx"
    ],
    [
      "xxxxxxxxxxxxxxxx",
      "x______________x",
      "x______________x",
      "x______________x",
      "x______________x",
      "x______________x",
      "x______________x",
      "x______________x",
      "x______________x",
      "x______________x",
      "x______________x",
      "x______________x",
      "x______________x",
      "x______________x",
      "x______________x",
      "xxxxxxxxxxxxxxxx"
    ],
    [
      "xxxxxxxxxxxxxxxx",
      "xxxxxxxxxxxxxxxx",
      "xxxxxxxxxxxxxxxx",
      "xxxxxxxxxxxxxxxx",
      "xxxxxxxxxxxxxxxx",
      "xxxxxxxxxxxxxxxx",
      "xxxxxxxxxxxxxxxx",
      "xxxxxxxxxxxxxxxx",
      "xxxxxxxxxxxxxxxx",
      "xxxxxxxxxxxxxxxx",
      "xxxxxxxxxxxxxxxx",
      "xxxxxxxxxxxxxxxx",
      "xxxxxxxxxxxxxxxx",
      "xxxxxxxxxxxxxxxx",
      "xxxxxxxxxxxxxxxx",
      "xxxxxxxxxxxxxxxx"
    ]
  ]
}
