{
  "xsize": 16,
  "zsize": 16,
  "refpalette": "wt8:test",
  "slices": [
    [
      "################",
      "################",
      "################",
      "################",
      "################",
      "################",
      "################",
      "################",
      "################",
      "################",
      "################",
      "################",
      "################",
      "################",
      "################",
      "################"
    ],
    [
      "################",
      "#______________#",
      "#______________#",
      "#______________#",
      "#______________G",
      "#______________#",
      "#______________#",
      "#______________#",
      "#S______________G",
      "#______________#",
      "#______________#",
      "#______________#",
      "#______________#",
      "#______________#",
      "#______________#",
      "################"
    ],
    [
      "################",
      "#______________#",
      "#______________#",
      "#______________#",
      "#______________#",
      "#______________#",
      "#______________#",
      "#______________#",
      "#______________#",
      "#______________#",
      "#______________#",
      "#______________#",
      "#______________#",
      "#______________#",
      "#______________#",
      "################"
    ],
    [
      "################",
      "#______________#",
      "#______________#",
      "#______________#",
      "#______________#",
      "#______________#",
      "#______________#",
      "#______________#",
      "#______________#",
      "#______________#",
      "#______________#",
      "#______________#",
      "#______________#",
      "#______________#",
      "#______________#",
      "################"
    ],
    [
      "################",
      "#______________#",
      "#______________#",
      "#______________#",
      "#______________#",
      "#______________#",
      "#______________#",
      "#______________#",
      "#______________#",
      "#______________#",
      "#______________#",
      "#______________#",
      "#______________#",
      "#______________#",
      "#______________#",
      "################"
    ],
    [
      "################",
      "################",
      "################",
      "################",
      "################",
      "################",
      "################",
      "################",
      "################",
      "################",
      "################",
      "################",
      "################",
      "################",
      "################",
      "################"
    ]
  ]
}
