{
  "xsize": 16,
  "zsize": 16,
  "refpalette": "mt:main",
  "slices": [
    [
      "DDDDDDDDDDDDDDDD",
      "DDDDDDDDDDDDDDDD",
      "DDDDDDDDDDDDDDDD",
      "DDDDDDDDDDDDDDDD",
      "DDDDDDDDDDDDDDDD",
      "DDDDDDDDDDDDDDDD",
      "DDDDDDDDDDDDDDDD",
      "DDDDDDDDDDDDDDDD",
      "DDDDDDDDDDDDDDDD",
      "DDDDDDDDDDDDDDDD",
      "DDDDDDDDDDDDDDDD",
      "DDDDDDDDDDDDDDDD",
      "DDDDDDDDDDDDDDDD",
      "DDDDDDDDDDDDDDDD",
      "DDDDDDDDDDDDDDDD",
      "DDDDDDDDDDDDDDDD"
    ],
    [
      "DDDDDDDDDDDDDDDD",
      "DDDDDDDDDDDDDDDD",
      "DDDDDDDDDDDDDDDD",
      "DDDDDDDDDDDDDDDD",
      "DDDDDDDDDDDDDDDD",
      "DDDDDDDDDDDDDDDD",
      "DDDDDDDDDDDDDDDD",
      "DDDDDDDDDDDDDDDD",
      "DDDDDDDDDDDDDDDD",
      "DDDDDDDDDDDDDDDD",
      "DDDDDDDDDDDDDDDD",
      "DDDDDDDDDDDDDDDD",
      "DDDDDDDDDDDDDDDD",
      "DDDDDDDDDDDDDDDD",
      "DDDDDDDDDDDDDDDD",
      "DDDDDDDDDDDDDDDD"
    ],
    [
      "DDDDDDDDDDDDDDDD",
      "DDDDDDDDDDDDDDDD",
      "DDDDDDDDDDDDDDDD",
      "DDDDDDDDDDDDDDDD",
      "DDDDDDDDDDDDDDDD",
      "DDDDDDDDDDDDDDDD",
      "DDDDDDDDDDDDDDDD",
      "DDDDDDDDDDDDDDDD",
      "DDDDDDDDDDDDDDDD",
      "DDDDDDDDDDDDDDDD",
      "DDDDDDDDDDDDDDDD",
      "DDDDDDDDDDDDDDDD",
      "DDDDDDDDDDDDDDDD",
      "DDDDDDDDDDDDDDDD",
      "DDDDDDDDDDDDDDDD",
      "DDDDDDDDDDDDDDDD"
    ],
    [
      "DDDDDDDDDDDDDDDD",
      "DDDDDDDDDDDDDDDD",
      "DDDDDDDDDDDDDDDD",
      "DDDDDDDDDDDDDDDD",
      "DDDDDDDDDDDDDDDD",
      "DDDDDDDDDDDDDDDD",
      "DDDDDDDDDDDDDDDD",
      "DDDDDDDDDDDDDDDD",
      "DDDDDDDDDDDDDDDD",
      "DDDDDDDDDDDDDDDD",
      "DDDDDDDDDDDDDDDD",
      "DDDDDDDDDDDDDDDD",
      "DDDDDDDDDDDDDDDD",
      "DDDDDDDDDDDDDDDD",
      "DDDDDDDDDDDDDDDD",
      "DDDDDDDDDDDDDDDD"
    ],
    [
      "DDDDDDDDDDDDDDDD",
      "DDDDDDDDDDDDDDDD",
      "DDDDDDDDDDDDDDDD",
      "DDDDDDDDDDDDDDDD",
      "DDDDDDDDDDDDDDDD",
      "DDDDDDDDDDDDDDDD",
      "DDDDDDDDDDDDDDDD",
      "DDDDDDDDDDDDDDDD",
      "DDDDDDDDDDDDDDDD",
      "DDDDDDDDDDDDDDDD",
      "DDDDDDDDDDDDDDDD",
      "DDDDDDDDDDDDDDDD",
      "DDDDDDDDDDDDDDDD",
      "DDDDDDDDDDDDDDDD",
      "DDDDDDDDDDDDDDDD",
      "DDDDDDDDDDDDDDDD"
    ],
    [
      "DDDDDDDDDDDDDDDD",
      "DDDDDDDDDDDDDDDD",
      "DDDDDDDDDDDDDDDD",
      "DDDDDDDDDDDDDDDD",
      "DDDDDDDDDDDDDDDD",
      "DDDDDDDDDDDDDDDD",
      "DDDDDDDDDDDDDDDD",
      "DDDDDDDDDDDDDDDD",
      "DDDDDDDDDDDDDDDD",
      "DDDDDDDDDDDDDDDD",
      "DDDDDDDDDDDDDDDD",
      "DDDDDDDDDDDDDDDD",
      "DDDDDDDDDDDDDDDD",
      "DDDDDDDDDDDDDDDD",
      "DDDDDDDDDDDDDDDD",
      "DDDDDDDDDDDDDDDD"
    ]
  ]
}
