{
  "xsize": 16,
  "zsize": 16,
  "refpalette": "mt:main",
  "slices": [
    [
      "EEEEEEEEEEEEEEEE",
      "EEEEEEEEEEEEEEEE",
      "EEEEEEEEEEEEEEEE",
      "EEEEEEEEEEEEEEEE",
      "EEEEEEEEEEEEEEEE",
      "EEEEEEEEEEEEEEEE",
      "EEEEEEEEEEEEEEEE",
      "EEEEEEEEEEEEEEEE",
      "EEEEEEEEEEEEEEEE",
      "EEEEEEEEEEEEEEEE",
      "EEEEEEEEEEEEEEEE",
      "EEEEEEEEEEEEEEEE",
      "EEEEEEEEEEEEEEEE",
      "EEEEEEEEEEEEEEEE",
      "EEEEEEEEEEEEEEEE",
      "EEEEEEEEEEEEEEEE"
    ],
    [
      "EEEEEEEEEEEEEEEE",
      "EEEEEEEEEEEEEEEE",
      "EEEEEEEEEEEEEEEE",
      "EEEEEEEEEEEEEEEE",
      "EEEEEEEEEEEEEEEE",
      "EEEEEEEEEEEEEEEE",
      "EEEEEEEEEEEEEEEE",
      "EEEEEEEEEEEEEEEE",
      "EEEEEEEEEEEEEEEE",
      "EEEEEEEEEEEEEEEE",
      "EEEEEEEEEEEEEEEE",
      "EEEEEEEEEEEEEEEE",
      "EEEEEEEEEEEEEEEE",
      "EEEEEEEEEEEEEEEE",
      "EEEEEEEEEEEEEEEE",
      "EEEEEEEEEEEEEEEE"
    ],
    [
      "EEEEEEEEEEEEEEEE",
      "EEEEEEEEEEEEEEEE",
      "EEEEEEEEEEEEEEEE",
      "EEEEEEEEEEEEEEEE",
      "EEEEEEEEEEEEEEEE",
      "EEEEEEEEEEEEEEEE",
      "EEEEEEEEEEEEEEEE",
      "EEEEEEEEEEEEEEEE",
      "EEEEEEEEEEEEEEEE",
      "EEEEEEEEEEEEEEEE",
      "EEEEEEEEEEEEEEEE",
      "EEEEEEEEEEEEEEEE",
      "EEEEEEEEEEEEEEEE",
      "EEEEEEEEEEEEEEEE",
      "EEEEEEEEEEEEEEEE",
      "EEEEEEEEEEEEEEEE"
    ],
    [
      "EEEEEEEEEEEEEEEE",
      "EEEEEEEEEEEEEEEE",
      "EEEEEEEEEEEEEEEE",
      "EEEEEEEEEEEEEEEE",
      "EEEEEEEEEEEEEEEE",
      "EEEEEEEEEEEEEEEE",
      "EEEEEEEEEEEEEEEE",
      "EEEEEEEEEEEEEEEE",
      "EEEEEEEEEEEEEEEE",
      "EEEEEEEEEEEEEEEE",
      "EEEEEEEEEEEEEEEE",
      "EEEEEEEEEEEEEEEE",
      "EEEEEEEEEEEEEEEE",
      "EEEEEEEEEEEEEEEE",
      "EEEEEEEEEEEEEEEE",
      "EEEEEEEEEEEEEEEE"
    ],
    [
      "EEEEEEEEEEEEEEEE",
      "EEEEEEEEEEEEEEEE",
      "EEEEEEEEEEEEEEEE",
      "EEEEEEEEEEEEEEEE",
      "EEEEEEEEEEEEEEEE",
      "EEEEEEEEEEEEEEEE",
      "EEEEEEEEEEEEEEEE",
      "EEEEEEEEEEEEEEEE",
      "EEEEEEEEEEEEEEEE",
      "EEEEEEEEEEEEEEEE",
      "EEEEEEEEEEEEEEEE",
      "EEEEEEEEEEEEEEEE",
      "EEEEEEEEEEEEEEEE",
      "EEEEEEEEEEEEEEEE",
      "EEEEEEEEEEEEEEEE",
      "EEEEEEEEEEEEEEEE"
    ],
    [
      "EEEEEEEEEEEEEEEE",
      "EEEEEEEEEEEEEEEE",
      "EEEEEEEEEEEEEEEE",
      "EEEEEEEEEEEEEEEE",
      "EEEEEEEEEEEEEEEE",
      "EEEEEEEEEEEEEEEE",
      "EEEEEEEEEEEEEEEE",
      "EEEEEEEEEEEEEEEE",
      "EEEEEEEEEEEEEEEE",
      "EEEEEEEEEEEEEEEE",
      "EEEEEEEEEEEEEEEE",
      "EEEEEEEEEEEEEEEE",
      "EEEEEEEEEEEEEEEE",
      "EEEEEEEEEEEEEEEE",
      "EEEEEEEEEEEEEEEE",
      "EEEEEEEEEEEEEEEE"
    ]
  ]
}
