{
  "xsize": 16,
  "zsize": 16,
  "refpalette": "j5:demo",
  "slices": [
    [
      "DDDDDDDDDDDDDDDD",
      "DDDDDDDDDDDDDDDD",
      "DDDDDDDDDDDDDDDD",
      "DDDDDDDDDDDDDDDD",
      "DDDDDDDDDDDDDDDD",
      "DDDDDDDDDDDDDDDD",
      "DDDDDDDDDDDDDDDD",
      "DDDDDDDDDDDDDDDD",
      "DDDDDDDDDDDDDDDD",
      "DDDDDDDDDDDDDDDD",
      "DDDDDDDDDDDDDDDD",
      "DDDDDDDDDDDDDDDD",
      "DDDDDDDDDDDDDDDD",
      "DDDDDDDDDDDDDDDD",
      "DDDDDDDDDDDDDDDD",
      "DDDDDDDDDDDDDDDD"
    ],
    [
      "DDDDDDDDDDDDDDDD",
      "D______________D",
      "D______________D",
      "D______________D",
      "D______________D",
      "D______________D",
      "D______________D",
      "D______________D",
      "D______________D",
      "D______________D",
      "D______________D",
      "D______________D",
      "D______________D",
      "D______________D",
      "D______________D",
      "DDDDDDDDDDDDDDDD"
    ],
    [
      "DDDDDDDDDDDDDDDD",
      "D______________D",
      "D______________D",
      "D______________D",
      "D______________D",
      "D______________D",
      "D______________D",
      "D______________D",
      "D______________D",
      "D______________D",
      "D______________D",
      "D______________D",
      "D______________D",
      "D______________D",
      "D______________D",
      "DDDDDDDDDDDDDDDD"
    ],
    [
      "DDDDDDDDDDDDDDDD",
      "D______________D",
      "D______________D",
      "D______________D",
      "D______________D",
      "D______________D",
      "D______________D",
      "D______________D",
      "D______________D",
      "D______________D",
      "D______________D",
      "D______________D",
      "D______________D",
      "D______________D",
      "D______________D",
      "DDDDDDDDDDDDDDDD"
    ],
    [
      "DDDDDDDDDDDDDDDD",
      "D______________D",
      "D______________D",
      "D______________D",
      "D______________D",
      "D______________D",
      "D______________D",
      "D______________D",
      "D______________D",
      "D______________D",
      "D______________D",
      "D______________D",
      "D______________D",
      "D______________D",
      "D______________D",
      "DDDDDDDDDDDDDDDD"
    ],
    [
      "DDDDDDDDDDDDDDDD",
      "D______________D",
      "D______________D",
      "D______________D",
      "D______________D",
      "D______________D",
      "D______________D",
      "D______________D",
      "D______________D",
      "D______________D",
      "D______________D",
      "D______________D",
      "D______________D",
      "D______________D",
      "D______________D",
      "DDDDDDDDDDDDDDDD"
    ]
  ]
}
