{
  "xsize": 16,
  "zsize": 16,
  "refpalette": "j5:demo",
  "slices": [
    [
      "GGGGGGGGGGGGGGGG",
      "GGGGGGGGGGGGGGGG",
      "GGGGGGGGGGGGGGGG",
      "GGGGGGGGGGGGGGGG",
      "GGGGGGGGGGGGGGGG",
      "GGGGGGGGGGGGGGGG",
      "GGGGGGGGGGGGGGGG",
      "GGGGGGGGGGGGGGGG",
      "GGGGGGGGGGGGGGGG",
      "GGGGGGGGGGGGGGGG",
      "GGGGGGGGGGGGGGGG",
      "GGGGGGGGGGGGGGGG",
      "GGGGGGGGGGGGGGGG",
      "GGGGGGGGGGGGGGGG",
      "GGGGGGGGGGGGGGGG",
      "GGGGGGGGGGGGGGGG"
    ],
    [
      "GGGGGGGGGGGGGGGG",
      "G______________G",
      "G______________G",
      "G______________G",
      "G______________G",
      "G______________G",
      "G______________G",
      "G______________G",
      "G______________G",
      "G______________G",
      "G______________G",
      "G______________G",
      "G______________G",
      "G______________G",
      "G______________G",
      "GGGGGGGGGGGGGGGG"
    ],
    [
      "GGGGGGGGGGGGGGGG",
      "G______________G",
      "G______________G",
      "G______________G",
      "G______________G",
      "G______________G",
      "G______________G",
      "G______________G",
      "G______________G",
      "G______________G",
      "G______________G",
      "G______________G",
      "G______________G",
      "G______________G",
      "G______________G",
      "GGGGGGGGGGGGGGGG"
    ],
    [
      "GGGGGGGGGGGGGGGG",
      "G______________G",
      "G______________G",
      "G______________G",
      "G______________G",
      "G______________G",
      "G______________G",
      "G______________G",
      "G______________G",
      "G______________G",
      "G______________G",
      "G______________G",
      "G______________G",
      "G______________G",
      "G______________G",
      "GGGGGGGGGGGGGGGG"
    ],
    [
      "GGGGGGGGGGGGGGGG",
      "G______________G",
      "G______________G",
      "G______________G",
      "G______________G",
      "G______________G",
      "G______________G",
      "G______________G",
      "G______________G",
      "G______________G",
      "G______________G",
      "G______________G",
      "G______________G",
      "G______________G",
      "G______________G",
      "GGGGGGGGGGGGGGGG"
    ],
    [
      "GGGGGGGGGGGGGGGG",
      "G______________G",
      "G______________G",
      "G______________G",
      "G______________G",
      "G______________G",
      "G______________G",
      "G______________G",
      "G______________G",
      "G______________G",
      "G______________G",
      "G______________G",
      "G______________G",
      "G______________G",
      "G______________G",
      "GGGGGGGGGGGGGGGG"
    ]
  ]
}
