{
  "xsize": 16,
  "zsize": 16,
  "refpalette": "j5:demo",
  "slices": [
    [
      "LLLLLLLLLLLLLLLL",
      "LLLLLLLLLLLLLLLL",
      "LLLLLLLLLLLLLLLL",
      "LLLLLLLLLLLLLLLL",
      "LLLLLLLLLLLLLLLL",
      "LLLLLLLLLLLLLLLL",
      "LLLLLLLLLLLLLLLL",
      "LLLLLLLLLLLLLLLL",
      "LLLLLLLLLLLLLLLL",
      "LLLLLLLLLLLLLLLL",
      "LLLLLLLLLLLLLLLL",
      "LLLLLLLLLLLLLLLL",
      "LLLLLLLLLLLLLLLL",
      "LLLLLLLLLLLLLLLL",
      "LLLLLLLLLLLLLLLL",
      "LLLLLLLLLLLLLLLL"
    ],
    [
      "LLLLLLLLLLLLLLLL",
      "L______________L",
      "L______________L",
      "L______________L",
      "L______________L",
      "L______________L",
      "L______________L",
      "L______________L",
      "L______________L",
      "L______________L",
      "L______________L",
      "L______________L",
      "L______________L",
      "L______________L",
      "L______________L",
      "LLLLLLLLLLLLLLLL"
    ],
    [
      "LLLLLLLLLLLLLLLL",
      "L______________L",
      "L______________L",
      "L______________L",
      "L______________L",
      "L______________L",
      "L______________L",
      "L______________L",
      "L______________L",
      "L______________L",
      "L______________L",
      "L______________L",
      "L______________L",
      "L______________L",
      "L______________L",
      "LLLLLLLLLLLLLLLL"
    ],
    [
      "LLLLLLLLLLLLLLLL",
      "L______________L",
      "L______________L",
      "L______________L",
      "L______________L",
      "L______________L",
      "L______________L",
      "L______________L",
      "L______________L",
      "L______________L",
      "L______________L",
      "L______________L",
      "L______________L",
      "L______________L",
      "L______________L",
      "LLLLLLLLLLLLLLLL"
    ],
    [
      "LLLLLLLLLLLLLLLL",
      "L______________L",
      "L______________L",
      "L______________L",
      "L______________L",
      "L______________L",
      "L______________L",
      "L______________L",
      "L______________L",
      "L______________L",
      "L______________L",
      "L______________L",
      "L______________L",
      "L______________L",
      "L______________L",
      "LLLLLLLLLLLLLLLL"
    ],
    [
      "LLLLLLLLLLLLLLLL",
      "L______________L",
      "L______________L",
      "L______________L",
      "L______________L",
      "L______________L",
      "L______________L",
      "L______________L",
      "L______________L",
      "L______________L",
      "L______________L",
      "L______________L",
      "L______________L",
      "L______________L",
      "L______________L",
      "LLLLLLLLLLLLLLLL"
    ]
  ]
}
