{
  "xsize": 16,
  "zsize": 16,
  "refpalette": "wt5:test",
  "slices": [
    [
      "EEEEEEEEEEEEEEEE",
      "EEEEEEEEEEEEEEEE",
      "EEEEEEEEEEEEEEEE",
      "EEEEEEEEEEEEEEEE",
      "EEEEEEEEEEEEEEEE",
      "EEEEEEEEEEEEEEEE",
      "EEEEEEEEEEEEEEEE",
      "EEEEEEEEEEEEEEEE",
      "EEEEEEEEEEEEEEEE",
      "EEEEEEEEEEEEEEEE",
      "EEEEEEEEEEEEEEEE",
      "EEEEEEEEEEEEEEEE",
      "EEEEEEEEEEEEEEEE",
      "EEEEEEEEEEEEEEEE",
      "EEEEEEEEEEEEEEEE",
      "EEEEEEEEEEEEEEEE"
    ],
    [
      "EEEEEEEEEEEEEEEE",
      "E______________E",
      "E______________E",
      "E______________E",
      "E______________E",
      "E______________E",
      "E______________E",
      "E______________E",
      "E______________E",
      "E______________E",
      "E______________E",
      "E______________E",
      "E______________E",
      "E______________E",
      "E______________E",
      "EEEEEEEEEEEEEEEE"
    ],
    [
      "EEEEEEEEEEEEEEEE",
      "E______________E",
      "E______________E",
      "E______________E",
      "E______________E",
      "E______________E",
      "E______________E",
      "E______________E",
      "E______________E",
      "E______________E",
      "E______________E",
      "E______________E",
      "E______________E",
      "E______________E",
      "E______________E",
      "EEEEEEEEEEEEEEEE"
    ],
    [
      "EEEEEEEEEEEEEEEE",
      "E______________E",
      "E______________E",
      "E______________E",
      "E______________E",
      "E______________E",
      "E______________E",
      "E______________E",
      "E______________E",
      "E______________E",
      "E______________E",
      "E______________E",
      "E______________E",
      "E______________E",
      "E______________E",
      "EEEEEEEEEEEEEEEE"
    ],
    [
      "EEEEEEEEEEEEEEEE",
      "E______________E",
      "E______________E",
      "E______________E",
      "E______________E",
      "E______________E",
      "E______________E",
      "E______________E",
      "E______________E",
      "E______________E",
      "E______________E",
      "E______________E",
      "E______________E",
      "E______________E",
      "E______________E",
      "EEEEEEEEEEEEEEEE"
    ],
    [
      "EEEEEEEEEEEEEEEE",
      "EEEEEEEEEEEEEEEE",
      "EEEEEEEEEEEEEEEE",
      "EEEEEEEEEEEEEEEE",
      "EEEEEEEEEEEEEEEE",
      "EEEEEEEEEEEEEEEE",
      "EEEEEEEEEEEEEEEE",
      "EEEEEEEEEEEEEEEE",
      "EEEEEEEEEEEEEEEE",
      "EEEEEEEEEEEEEEEE",
      "EEEEEEEEEEEEEEEE",
      "EEEEEEEEEEEEEEEE",
      "EEEEEEEEEEEEEEEE",
      "EEEEEEEEEEEEEEEE",
      "EEEEEEEEEEEEEEEE",
      "EEEEEEEEEEEEEEEE"
    ]
  ]
}
