{
  "xsize": 16,
  "zsize": 16,
  "refpalette": "wt5:test",
  "slices": [
    [
      "mmmmmmmmmmmmmmmm",
      "mmmmmmmmmmmmmmmm",
      "mmmmmmmmmmmmmmmm",
      "mmmmmmmmmmmmmmmm",
      "mmmmmmmmmmmmmmmm",
      "mmmmmmmmmmmmmmmm",
      "mmmmmmmmmmmmmmmm",
      "mmmmmmmmmmmmmmmm",
      "mmmmmmmmmmmmmmmm",
      "mmmmmmmmmmmmmmmm",
      "mmmmmmmmmmmmmmmm",
      "mmmmmmmmmmmmmmmm",
      "mmmmmmmmmmmmmmmm",
      "mmmmmmmmmmmmmmmm",
      "mmmmmmmmmmmmmmmm",
      "mmmmmmmmmmmmmmmm"
    ],
    [
      "mmmmmmmmmmmmmmmm",
      "m______________m",
      "m______________m",
      "m______________m",
      "m______________m",
      "m______________m",
      "m______________m",
      "m______________m",
      "m______________m",
      "m______________m",
      "m______________m",
      "m______________m",
      "m______________m",
      "m______________m",
      "m______________m",
      "mmmmmmmmmmmmmmmm"
    ],
    [
      "mmmmmmmmmmmmmmmm",
      "m______________m",
      "m______________m",
      "m______________m",
      "m______________m",
      "m______________m",
      "m______________m",
      "m______________m",
      "m______________m",
      "m______________m",
      "m______________m",
      "m______________m",
      "m______________m",
      "m______________m",
      "m______________m",
      "mmmmmmmmmmmmmmmm"
    ],
    [
      "mmmmmmmmmmmmmmmm",
      "m______________m",
      "m______________m",
      "m______________m",
      "m______________m",
      "m______________m",
      "m______________m",
      "m______________m",
      "m______________m",
      "m______________m",
      "m______________m",
      "m______________m",
      "m______________m",
      "m______________m",
      "m______________m",
      "mmmmmmmmmmmmmmmm"
    ],
    [
      "mmmmmmmmmmmmmmmm",
      "m______________m",
      "m______________m",
      "m______________m",
      "m______________m",
      "m______________m",
      "m______________m",
      "m______________m",
      "m______________m",
      "m______________m",
      "m______________m",
      "m______________m",
      "m______________m",
      "m______________m",
      "m______________m",
      "mmmmmmmmmmmmmmmm"
    ],
    [
      "mmmmmmmmmmmmmmmm",
      "mmmmmmmmmmmmmmmm",
      "mmmmmmmmmmmmmmmm",
      "mmmmmmmmmmmmmmmm",
      "mmmmmmmmmmmmmmmm",
      "mmmmmmmmmmmmmmmm",
      "mmmmmmmmmmmmmmmm",
      "mmmmmmmmmmmmmmmm",
      "mmmmmmmmmmmmmmmm",
      "mmmmmmmmmmmmmmmm",
      "mmmmmmmmmmmmmmmm",
      "mmmmmmmmmmmmmmmm",
      "mmmmmmmmmmmmmmmm",
      "mmmmmmmmmmmmmmmm",
      "mmmmmmmmmmmmmmmm",
      "mmmmmmmmmmmmmmmm"
    ]
  ]
}
