{
  "xsize": 16,
  "zsize": 16,
  "refpalette": "wt5:test",
  "slices": [
    [
      "################",
      "################",
      "################",
      "################",
      "################",
      "################",
      "################",
      "################",
      "################",
      "################",
      "################",
      "################",
      "################",
      "################",
      "################",
      "################"
    ],
    [
      "################",
      "#______________#",
      "#______________#",
      "#______________#",
      "#______________#",
      "#______________#",
      "#______________#",
      "#______________#",
      "#___n___n___n__#",
      "#______________#",
      "#______________#",
      "#______________#",
      "#______________#",
      "#______________#",
      "#______________#",
      "################"
    ],
    [
      "################",
      "#______________#",
      "#______________#",
      "#______________#",
      "#______________#",
      "#______________#",
      "#______________#",
      "#______________#",
      "#______________#",
      "#______________#",
      "#______________#",
      "#______________#",
      "#______________#",
      "#______________#",
      "#______________#",
      "################"
    ],
    [
      "################",
      "#______________#",
      "#______________#",
      "#______________#",
      "#______________#",
      "#______________#",
      "#______________#",
      "#______________#",
      "#______________#",
      "#______________#",
      "#______________#",
      "#______________#",
      "#______________#",
      "#______________#",
      "#______________#",
      "################"
    ],
    [
      "################",
      "#______________#",
      "#______________#",
      "#______________#",
      "#______________#",
      "#______________#",
      "#______________#",
      "#______________#",
      "#______________#",
      "#______________#",
      "#______________#",
      "#______________#",
      "#______________#",
      "#______________#",
      "#______________#",
      "################"
    ],
    [
      "################",
      "################",
      "################",
      "################",
      "################",
      "################",
      "################",
      "################",
      "################",
      "################",
      "################",
      "################",
      "################",
      "################",
      "################",
      "################"
    ]
  ]
}
