{
  "xsize": 16,
  "zsize": 16,
  "refpalette": "wt7:test",
  "slices": [
    [
      "GGGGGGGGGGGGGGGG",
      "GGGGGGGGGGGGGGGG",
      "GGGGGGGGGGGGGGGG",
      "GGGGGGGGGGGGGGGG",
      "GGGGGGGGGGGGGGGG",
      "GGGGGGGGGGGGGGGG",
      "GGGGGGGGGGGGGGGG",
      "GGGGGGGGGGGGGGGG",
      "GGGGGGGGGGGGGGGG",
      "GGGGGGGGGGGGGGGG",
      "GGGGGGGGGGGGGGGG",
      "GGGGGGGGGGGGGGGG",
      "GGGGGGGGGGGGGGGG",
      "GGGGGGGGGGGGGGGG",
      "GGGGGGGGGGGGGGGG",
      "GGGGGGGGGGGGGGGG"
    ],
    [
      "GGGGGGGGGGGGGGGG",
      "G______________G",
      "G______________G",
      "G______________G",
      "G______________G",
      "G______________G",
      "G______________G",
      "G______________G",
      "G______________G",
      "G______________G",
      "G______________G",
      "G______________G",
      "G______________G",
      "G______________G",
      "G______________G",
      "GGGGGGGGGGGGGGGG"
    ],
    [
      "GGGGGGGGGGGGGGGG",
      "G______________G",
      "G______________G",
      "G______________G",
      "G______________G",
      "G______________G",
      "G______________G",
      "G______________G",
      "G______________G",
      "G______________G",
      "G______________G",
      "G______________G",
      "G______________G",
      "G______________G",
      "G______________G",
      "GGGGGGGGGGGGGGGG"
    ],
    [
      "GGGGGGGGGGGGGGGG",
      "G______________G",
      "G______________G",
      "G______________G",
      "G______________G",
      "G______________G",
      "G______________G",
      "G______________G",
      "G______________G",
      "G______________G",
      "G______________G",
      "G______________G",
      "G______________G",
      "G______________G",
      "G______________G",
      "GGGGGGGGGGGGGGGG"
    ],
    [
      "GGGGGGGGGGGGGGGG",
      "G______________G",
      "G______________G",
      "G______________G",
      "G______________G",
      "G______________G",
      "G______________G",
      "G______________G",
      "G______________G",
      "G______________G",
      "G______________G",
      "G______________G",
      "G______________G",
      "G______________G",
      "G______________G",
      "GGGGGGGGGGGGGGGG"
    ],
    [
      "GGGGGGGGGGGGGGGG",
      "GGGGGGGGGGGGGGGG",
      "GGGGGGGGGGGGGGGG",
      "GGGGGGGGGGGGGGGG",
      "GGGGGGGGGGGGGGGG",
      "GGGGGGGGGGGGGGGG",
      "GGGGGGGGGGGGGGGG",
      "GGGGGGGGGGGGGGGG",
      "GGGGGGGGGGGGGGGG",
      "GGGGGGGGGGGGGGGG",
      "GGGGGGGGGGGGGGGG",
      "GGGGGGGGGGGGGGGG",
      "GGGGGGGGGGGGGGGG",
      "GGGGGGGGGGGGGGGG",
      "GGGGGGGGGGGGGGGG",
      "GGGGGGGGGGGGGGGG"
    ]
  ]
}
