{
  "xsize": 16,
  "zsize": 16,
  "refpalette": "wt7:circ",
  "slices": [
    [
      "################",
      "################",
      "################",
      "################",
      "################",
      "################",
      "################",
      "################",
      "################",
      "################",
      "################",
      "################",
      "################",
      "################",
      "################",
      "################"
    ],
    [
      "ѰѰѰѰѰѰѰѰѰѰѰѰѰѰѰѰ",
      "Ѱ______________Ѱ",
      "Ѱ______________Ѱ",
      "Ѱ______________Ѱ",
      "Ѱ______________Ѱ",
      "Ѱ______________Ѱ",
      "Ѱ______________Ѱ",
      "Ѱ______________Ѱ",
      "Ѱ______________Ѱ",
      "Ѱ______________Ѱ",
      "Ѱ______________Ѱ",
      "Ѱ______________Ѱ",
      "Ѱ______________Ѱ",
      "Ѱ______________Ѱ",
      "Ѱ______________Ѱ",
      "ѰѰѰѰѰѰѰѰѰѰѰѰѰѰѰѰ"
    ],
    [
      "ѰѰѰѰѰѰѰѰѰѰѰѰѰѰѰѰ",
      "Ѱ______________Ѱ",
      "Ѱ______________Ѱ",
      "Ѱ______________Ѱ",
      "Ѱ______________Ѱ",
      "Ѱ______________Ѱ",
      "Ѱ______________Ѱ",
      "Ѱ______________Ѱ",
      "Ѱ______________Ѱ",
      "Ѱ______________Ѱ",
      "Ѱ______________Ѱ",
      "Ѱ______________Ѱ",
      "Ѱ______________Ѱ",
      "Ѱ______________Ѱ",
      "Ѱ______________Ѱ",
      "ѰѰѰѰѰѰѰѰѰѰѰѰѰѰѰѰ"
    ],
    [
      "ѰѰѰѰѰѰѰѰѰѰѰѰѰѰѰѰ",
      "Ѱ______________Ѱ",
      "Ѱ______________Ѱ",
      "Ѱ______________Ѱ",
      "Ѱ______________Ѱ",
      "Ѱ______________Ѱ",
      "Ѱ______________Ѱ",
      "Ѱ______________Ѱ",
      "Ѱ______________Ѱ",
      "Ѱ______________Ѱ",
      "Ѱ______________Ѱ",
      "Ѱ______________Ѱ",
      "Ѱ______________Ѱ",
      "Ѱ______________Ѱ",
      "Ѱ______________Ѱ",
      "ѰѰѰѰѰѰѰѰѰѰѰѰѰѰѰѰ"
    ],
    [
      "ѰѰѰѰѰѰѰѰѰѰѰѰѰѰѰѰ",
      "Ѱ______________Ѱ",
      "Ѱ______________Ѱ",
      "Ѱ______________Ѱ",
      "Ѱ______________Ѱ",
      "Ѱ______________Ѱ",
      "Ѱ______________Ѱ",
      "Ѱ______________Ѱ",
      "Ѱ______________Ѱ",
      "Ѱ______________Ѱ",
      "Ѱ______________Ѱ",
      "Ѱ______________Ѱ",
      "Ѱ______________Ѱ",
      "Ѱ______________Ѱ",
      "Ѱ______________Ѱ",
      "ѰѰѰѰѰѰѰѰѰѰѰѰѰѰѰѰ"
    ],
    [
      "################",
      "################",
      "################",
      "################",
      "################",
      "################",
      "################",
      "################",
      "################",
      "################",
      "################",
      "################",
      "################",
      "################",
      "################",
      "################"
    ]
  ]
}
