{
  "xsize": 16,
  "zsize": 16,
  "refpalette": "wt7:test",
  "slices": [
    [
      "ZZZZZZZZZZZZZZZZ",
      "ZZZZZZZZZZZZZZZZ",
      "ZZZZZZZZZZZZZZZZ",
      "ZZZZZZZZZZZZZZZZ",
      "ZZZZZZZZZZZZZZZZ",
      "ZZZZZZZZZZZZZZZZ",
      "ZZZZZZZZZZZZZZZZ",
      "ZZZZZZZZZZZZZZZZ",
      "ZZZZZZZZZZZZZZZZ",
      "ZZZZZZZZZZZZZZZZ",
      "ZZZZZZZZZZZZZZZZ",
      "ZZZZZZZZZZZZZZZZ",
      "ZZZZZZZZZZZZZZZZ",
      "ZZZZZZZZZZZZZZZZ",
      "ZZZZZZZZZZZZZZZZ",
      "ZZZZZZZZZZZZZZZZ"
    ],
    [
      "ZZZZZZZZZZZZZZZZ",
      "Z______________Z",
      "Z______________Z",
      "Z______________Z",
      "Z______________Z",
      "Z______________Z",
      "Z______________Z",
      "Z______________Z",
      "Z______________Z",
      "Z______________Z",
      "Z______________Z",
      "Z______________Z",
      "Z______________Z",
      "Z______________Z",
      "Z______________Z",
      "ZZZZZZZZZZZZZZZZ"
    ],
    [
      "ZZZZZZZZZZZZZZZZ",
      "Z______________Z",
      "Z______________Z",
      "Z______________Z",
      "Z______________Z",
      "Z______________Z",
      "Z______________Z",
      "Z______________Z",
      "Z______________Z",
      "Z______________Z",
      "Z______________Z",
      "Z______________Z",
      "Z______________Z",
      "Z______________Z",
      "Z______________Z",
      "ZZZZZZZZZZZZZZZZ"
    ],
    [
      "ZZZZZZZZZZZZZZZZ",
      "Z______________Z",
      "Z______________Z",
      "Z______________Z",
      "Z______________Z",
      "Z______________Z",
      "Z______________Z",
      "Z______________Z",
      "Z______________Z",
      "Z______________Z",
      "Z______________Z",
      "Z______________Z",
      "Z______________Z",
      "Z______________Z",
      "Z______________Z",
      "ZZZZZZZZZZZZZZZZ"
    ],
    [
      "ZZZZZZZZZZZZZZZZ",
      "Z______________Z",
      "Z______________Z",
      "Z______________Z",
      "Z______________Z",
      "Z______________Z",
      "Z______________Z",
      "Z______________Z",
      "Z______________Z",
      "Z______________Z",
      "Z______________Z",
      "Z______________Z",
      "Z______________Z",
      "Z______________Z",
      "Z______________Z",
      "ZZZZZZZZZZZZZZZZ"
    ],
    [
      "ZZZZZZZZZZZZZZZZ",
      "ZZZZZZZZZZZZZZZZ",
      "ZZZZZZZZZZZZZZZZ",
      "ZZZZZZZZZZZZZZZZ",
      "ZZZZZZZZZZZZZZZZ",
      "ZZZZZZZZZZZZZZZZ",
      "ZZZZZZZZZZZZZZZZ",
      "ZZZZZZZZZZZZZZZZ",
      "ZZZZZZZZZZZZZZZZ",
      "ZZZZZZZZZZZZZZZZ",
      "ZZZZZZZZZZZZZZZZ",
      "ZZZZZZZZZZZZZZZZ",
      "ZZZZZZZZZZZZZZZZ",
      "ZZZZZZZZZZZZZZZZ",
      "ZZZZZZZZZZZZZZZZ",
      "ZZZZZZZZZZZZZZZZ"
    ]
  ]
}
