{
  "xsize": 16,
  "zsize": 16,
  "refpalette": "wt7:test",
  "slices": [
    [
      "################",
      "################",
      "################",
      "################",
      "################",
      "################",
      "################",
      "################",
      "################",
      "################",
      "################",
      "################",
      "################",
      "################",
      "################",
      "################"
    ],
    [
      "################",
      "#______________#",
      "#______________#",
      "#______________#",
      "#______________#",
      "#______________#",
      "#______________#",
      "#______________#",
      "#__c__c__c__c__#",
      "#______________#",
      "#______________#",
      "#______________#",
      "#______________#",
      "#______________#",
      "#______________#",
      "################"
    ],
    [
      "################",
      "#______________#",
      "#______________#",
      "#______________#",
      "#______________#",
      "#______________#",
      "#______________#",
      "#______________#",
      "#______________#",
      "#______________#",
      "#______________#",
      "#______________#",
      "#______________#",
      "#______________#",
      "#______________#",
      "################"
    ],
    [
      "################",
      "#______________#",
      "#______________#",
      "#______________#",
      "#______________#",
      "#______________#",
      "#______________#",
      "#______________#",
      "#______________#",
      "#______________#",
      "#______________#",
      "#______________#",
      "#______________#",
      "#______________#",
      "#______________#",
      "################"
    ],
    [
      "################",
      "#______________#",
      "#______________#",
      "#______________#",
      "#______________#",
      "#______________#",
      "#______________#",
      "#______________#",
      "#______________#",
      "#______________#",
      "#______________#",
      "#______________#",
      "#______________#",
      "#______________#",
      "#______________#",
      "################"
    ],
    [
      "################",
      "################",
      "################",
      "################",
      "################",
      "################",
      "################",
      "################",
      "################",
      "################",
      "################",
      "################",
      "################",
      "################",
      "################",
      "################"
    ]
  ]
}
