{
  "xsize": 16,
  "zsize": 16,
  "refpalette": "wt7:prec_part",
  "slices": [
    [
      "################",
      "################",
      "################",
      "################",
      "################",
      "################",
      "################",
      "################",
      "################",
      "################",
      "################",
      "################",
      "################",
      "################",
      "################",
      "################"
    ],
    [
      "字字字字字字字字字字字字字字字字",
      "字______________字",
      "字______________字",
      "字______________字",
      "字______________字",
      "字______________字",
      "字______________字",
      "字______________字",
      "字______________字",
      "字______________字",
      "字______________字",
      "字______________字",
      "字______________字",
      "字______________字",
      "字______________字",
      "字字字字字字字字字字字字字字字字"
    ],
    [
      "字字字字字字字字字字字字字字字字",
      "字______________字",
      "字______________字",
      "字______________字",
      "字______________字",
      "字______________字",
      "字______________字",
      "字______________字",
      "字______________字",
      "字______________字",
      "字______________字",
      "字______________字",
      "字______________字",
      "字______________字",
      "字______________字",
      "字字字字字字字字字字字字字字字字"
    ],
    [
      "字字字字字字字字字字字字字字字字",
      "字______________字",
      "字______________字",
      "字______________字",
      "字______________字",
      "字______________字",
      "字______________字",
      "字______________字",
      "字______________字",
      "字______________字",
      "字______________字",
      "字______________字",
      "字______________字",
      "字______________字",
      "字______________字",
      "字字字字字字字字字字字字字字字字"
    ],
    [
      "字字字字字字字字字字字字字字字字",
      "字______________字",
      "字______________字",
      "字______________字",
      "字______________字",
      "字______________字",
      "字______________字",
      "字______________字",
      "字______________字",
      "字______________字",
      "字______________字",
      "字______________字",
      "字______________字",
      "字______________字",
      "字______________字",
      "字字字字字字字字字字字字字字字字"
    ],
    [
      "################",
      "################",
      "################",
      "################",
      "################",
      "################",
      "################",
      "################",
      "################",
      "################",
      "################",
      "################",
      "################",
      "################",
      "################",
      "################"
    ]
  ]
}
