{
  "xsize": 16,
  "zsize": 16,
  "slices": [
    [
      "################",
      "################",
      "################",
      "################",
      "################",
      "################",
      "################",
      "################",
      "################",
      "################",
      "################",
      "################",
      "################",
      "################",
      "################",
      "################"
    ],
    [
      "AAAAAAAAAAAAAAAA",
      "A______________A",
      "A______________A",
      "A______________A",
      "A______________A",
      "A______________A",
      "A______________A",
      "A______________A",
      "A______________A",
      "A______________A",
      "A______________A",
      "A______________A",
      "A______________A",
      "A______________A",
      "A______________A",
      "AAAAAAAAAAAAAAAA"
    ],
    [
      "AAAAAAAAAAAAAAAA",
      "A______________A",
      "A______________A",
      "A______________A",
      "A______________A",
      "A______________A",
      "A______________A",
      "A______________A",
      "A______________A",
      "A______________A",
      "A______________A",
      "A______________A",
      "A______________A",
      "A______________A",
      "A______________A",
      "AAAAAAAAAAAAAAAA"
    ],
    [
      "AAAAAAAAAAAAAAAA",
      "A______________A",
      "A______________A",
      "A______________A",
      "A______________A",
      "A______________A",
      "A______________A",
      "A______________A",
      "A______________A",
      "A______________A",
      "A______________A",
      "A______________A",
      "A______________A",
      "A______________A",
      "A______________A",
      "AAAAAAAAAAAAAAAA"
    ],
    [
      "AAAAAAAAAAAAAAAA",
      "A______________A",
      "A______________A",
      "A______________A",
      "A______________A",
      "A______________A",
      "A______________A",
      "A______________A",
      "A______________A",
      "A______________A",
      "A______________A",
      "A______________A",
      "A______________A",
      "A______________A",
      "A______________A",
      "AAAAAAAAAAAAAAAA"
    ],
    [
      "################",
      "################",
      "################",
      "################",
      "################",
      "################",
      "################",
      "################",
      "################",
      "################",
      "################",
      "################",
      "################",
      "################",
      "################",
      "################"
    ]
  ]
}
