{
  "xsize": 16,
  "zsize": 16,
  "refpalette": "wt7:test",
  "slices": [
    [
      "DDDDDDDDDDDDDDDD",
      "DDDDDDDDDDDDDDDD",
      "DDDDDDDDDDDDDDDD",
      "DDDDDDDDDDDDDDDD",
      "DDDDDDDDDDDDDDDD",
      "DDDDDDDDDDDDDDDD",
      "DDDDDDDDDDDDDDDD",
      "DDDDDDDDDDDDDDDD",
      "DDDDDDDDDDDDDDDD",
      "DDDDDDDDDDDDDDDD",
      "DDDDDDDDDDDDDDDD",
      "DDDDDDDDDDDDDDDD",
      "DDDDDDDDDDDDDDDD",
      "DDDDDDDDDDDDDDDD",
      "DDDDDDDDDDDDDDDD",
      "DDDDDDDDDDDDDDDD"
    ],
    [
      "DDDDDDDDDDDDDDDD",
      "D______________D",
      "D______________D",
      "D______________D",
      "D______________D",
      "D______________D",
      "D______________D",
      "D______________D",
      "D______________D",
      "D______________D",
      "D______________D",
      "D______________D",
      "D______________D",
      "D______________D",
      "D______________D",
      "DDDDDDDDDDDDDDDD"
    ],
    [
      "DDDDDDDDDDDDDDDD",
      "D______________D",
      "D______________D",
      "D______________D",
      "D______________D",
      "D______________D",
      "D______________D",
      "D______________D",
      "D______________D",
      "D______________D",
      "D______________D",
      "D______________D",
      "D______________D",
      "D______________D",
      "D______________D",
      "DDDDDDDDDDDDDDDD"
    ],
    [
      "DDDDDDDDDDDDDDDD",
      "D______________D",
      "D______________D",
      "D______________D",
      "D______________D",
      "D______________D",
      "D______________D",
      "D______________D",
      "D______________D",
      "D______________D",
      "D______________D",
      "D______________D",
      "D______________D",
      "D______________D",
      "D______________D",
      "DDDDDDDDDDDDDDDD"
    ],
    [
      "DDDDDDDDDDDDDDDD",
      "D______________D",
      "D______________D",
      "D______________D",
      "D______________D",
      "D______________D",
      "D______________D",
      "D______________D",
      "D______________D",
      "D______________D",
      "D______________D",
      "D______________D",
      "D______________D",
      "D______________D",
      "D______________D",
      "DDDDDDDDDDDDDDDD"
    ],
    [
      "DDDDDDDDDDDDDDDD",
      "DDDDDDDDDDDDDDDD",
      "DDDDDDDDDDDDDDDD",
      "DDDDDDDDDDDDDDDD",
      "DDDDDDDDDDDDDDDD",
      "DDDDDDDDDDDDDDDD",
      "DDDDDDDDDDDDDDDD",
      "DDDDDDDDDDDDDDDD",
      "DDDDDDDDDDDDDDDD",
      "DDDDDDDDDDDDDDDD",
      "DDDDDDDDDDDDDDDD",
      "DDDDDDDDDDDDDDDD",
      "DDDDDDDDDDDDDDDD",
      "DDDDDDDDDDDDDDDD",
      "DDDDDDDDDDDDDDDD",
      "DDDDDDDDDDDDDDDD"
    ]
  ]
}
