{
  "xsize": 16,
  "zsize": 16,
  "refpalette": "mycity:tower",
  "slices": [
    [
      "γγγγγγγγγγγγγγγγ",
      "γγγγγγγγγγγγγγγγ",
      "γγγγγγγγγγγγγγγγ",
      "γγγγγγγγγγγγγγγγ",
      "γγγγγγγγγγγγγγγγ",
      "γγγγγγγγγγγγγγγγ",
      "γγγγγγγγγγγγγγγγ",
      "γγγγγγγγγγγγγγγγ",
      "γγγγγγγγγγγγγγγγ",
      "γγγγγγγγγγγγγγγγ",
      "γγγγγγγγγγγγγγγγ",
      "γγγγγγγγγγγγγγγγ",
      "γγγγγγγγγγγγγγγγ",
      "γγγγγγγγγγγγγγγγ",
      "γγγγγγγγγγγγγγγγ",
      "γγγγγγγγγγγγγγγγ"
    ],
    [
      "αααααααααααααααα",
      "α              α",
      "α              α",
      "α  εε          α",
      "α              α",
      "α              α",
      "α              α",
      "α              α",
      "α              α",
      "α              α",
      "α              α",
      "α              α",
      "α              α",
      "α              α",
      "α              α",
      "αααααααααααααααα"
    ],
    [
      "ααααββββββββαααα",
      "α              α",
      "α              α",
      "α              α",
      "β              β",
      "β              β",
      "β              β",
      "β              β",
      "β              β",
      "β              β",
      "β              β",
      "β              β",
      "α              α",
      "α              α",
      "α              α",
      "ααααββββββββαααα"
    ],
    [
      "ααααββββββββαααα",
      "α              α",
      "α              α",
      "α              α",
      "β              β",
      "β              β",
      "β              β",
      "β              β",
      "β              β",
      "β              β",
      "β              β",
      "β              β",
      "α              α",
      "α              α",
      "α              α",
      "ααααββββββββαααα"
    ],
    [
      "αααααααααααααααα",
      "α              α",
      "α              α",
      "α              α",
      "α              α",
      "α              α",
      "α              α",
      "α              α",
      "α              α",
      "α              α",
      "α              α",
      "α              α",
      "α              α",
      "α              α",
      "α              α",
      "αααααααααααααααα"
    ],
    [
      "αααααααααααααααα",
      "α              α",
      "α              α",
      "α              α",
      "α              α",
      "α              α",
      "α              α",
      "α              α",
      "α              α",
      "α              α",
      "α              α",
      "α              α",
      "α              α",
      "α              α",
      "α              α",
      "αααααααααααααααα"
    ]
  ]
}
