{
  "xsize": 16,
  "zsize": 16,
  "refpalette": "wikitest:test",
  "slices": [
    [
      "PPPPPPPPPPPPPPPP",
      "PPPPPPPPPPPPPPPP",
      "PPPPPPPPPPPPPPPP",
      "PPPPPPPPPPPPPPPP",
      "PPPPPPPPPPPPPPPP",
      "PPPPPPPPPPPPPPPP",
      "PPPPPPPPPPPPPPPP",
      "PPPPPPPPPPPPPPPP",
      "PPPPPPPPPPPPPPPP",
      "PPPPPPPPPPPPPPPP",
      "PPPPPPPPPPPPPPPP",
      "PPPPPPPPPPPPPPPP",
      "PPPPPPPPPPPPPPPP",
      "PPPPPPPPPPPPPPPP",
      "PPPPPPPPPPPPPPPP",
      "PPPPPPPPPPPPPPPP"
    ],
    [
      "PPPPPPPPPPPPPPPP",
      "P______________P",
      "P______________P",
      "P______________P",
      "P______________P",
      "P______________P",
      "P______________P",
      "P______________P",
      "P______________P",
      "P______________P",
      "P______________P",
      "P______________P",
      "P______________P",
      "P______________P",
      "P______________P",
      "PPPPPPPPPPPPPPPP"
    ],
    [
      "PPPPPPPPPPPPPPPP",
      "P______________P",
      "P______________P",
      "P______________P",
      "P______________P",
      "P______________P",
      "P______________P",
      "P______________P",
      "P______________P",
      "P______________P",
      "P______________P",
      "P______________P",
      "P______________P",
      "P______________P",
      "P______________P",
      "PPPPPPPPPPPPPPPP"
    ],
    [
      "PPPPPPPPPPPPPPPP",
      "P______________P",
      "P______________P",
      "P______________P",
      "P______________P",
      "P______________P",
      "P______________P",
      "P______________P",
      "P______________P",
      "P______________P",
      "P______________P",
      "P______________P",
      "P______________P",
      "P______________P",
      "P______________P",
      "PPPPPPPPPPPPPPPP"
    ],
    [
      "PPPPPPPPPPPPPPPP",
      "P______________P",
      "P______________P",
      "P______________P",
      "P______________P",
      "P______________P",
      "P______________P",
      "P______________P",
      "P______________P",
      "P______________P",
      "P______________P",
      "P______________P",
      "P______________P",
      "P______________P",
      "P______________P",
      "PPPPPPPPPPPPPPPP"
    ],
    [
      "PPPPPPPPPPPPPPPP",
      "PPPPPPPPPPPPPPPP",
      "PPPPPPPPPPPPPPPP",
      "PPPPPPPPPPPPPPPP",
      "PPPPPPPPPPPPPPPP",
      "PPPPPPPPPPPPPPPP",
      "PPPPPPPPPPPPPPPP",
      "PPPPPPPPPPPPPPPP",
      "PPPPPPPPPPPPPPPP",
      "PPPPPPPPPPPPPPPP",
      "PPPPPPPPPPPPPPPP",
      "PPPPPPPPPPPPPPPP",
      "PPPPPPPPPPPPPPPP",
      "PPPPPPPPPPPPPPPP",
      "PPPPPPPPPPPPPPPP",
      "PPPPPPPPPPPPPPPP"
    ]
  ]
}
