{
  "xsize": 16,
  "zsize": 16,
  "refpalette": "wikitest:test",
  "slices": [
    [
      "LLLLLLLLLLLLLLLL",
      "LLLLLLLLLLLLLLLL",
      "LLLLLLLLLLLLLLLL",
      "LLLLLLLLLLLLLLLL",
      "LLLLLLLLLLLLLLLL",
      "LLLLLLLLLLLLLLLL",
      "LLLLLLLLLLLLLLLL",
      "LLLLLLLLLLLLLLLL",
      "LLLLLLLLLLLLLLLL",
      "LLLLLLLLLLLLLLLL",
      "LLLLLLLLLLLLLLLL",
      "LLLLLLLLLLLLLLLL",
      "LLLLLLLLLLLLLLLL",
      "LLLLLLLLLLLLLLLL",
      "LLLLLLLLLLLLLLLL",
      "LLLLLLLLLLLLLLLL"
    ],
    [
      "LLLLLLLLLLLLLLLL",
      "L______________L",
      "L______________L",
      "L______________L",
      "L______________L",
      "L______________L",
      "L______________L",
      "L______________L",
      "L______________L",
      "L______________L",
      "L______________L",
      "L______________L",
      "L______________L",
      "L______________L",
      "L______________L",
      "LLLLLLLLLLLLLLLL"
    ],
    [
      "LLLLLLLLLLLLLLLL",
      "L______________L",
      "L______________L",
      "L______________L",
      "L______________L",
      "L______________L",
      "L______________L",
      "L______________L",
      "L______________L",
      "L______________L",
      "L______________L",
      "L______________L",
      "L______________L",
      "L______________L",
      "L______________L",
      "LLLLLLLLLLLLLLLL"
    ],
    [
      "LLLLLLLLLLLLLLLL",
      "L______________L",
      "L______________L",
      "L______________L",
      "L______________L",
      "L______________L",
      "L______________L",
      "L______________L",
      "L______________L",
      "L______________L",
      "L______________L",
      "L______________L",
      "L______________L",
      "L______________L",
      "L______________L",
      "LLLLLLLLLLLLLLLL"
    ],
    [
      "LLLLLLLLLLLLLLLL",
      "L______________L",
      "L______________L",
      "L______________L",
      "L______________L",
      "L______________L",
      "L______________L",
      "L______________L",
      "L______________L",
      "L______________L",
      "L______________L",
      "L______________L",
      "L______________L",
      "L______________L",
      "L______________L",
      "LLLLLLLLLLLLLLLL"
    ],
    [
      "LLLLLLLLLLLLLLLL",
      "LLLLLLLLLLLLLLLL",
      "LLLLLLLLLLLLLLLL",
      "LLLLLLLLLLLLLLLL",
      "LLLLLLLLLLLLLLLL",
      "LLLLLLLLLLLLLLLL",
      "LLLLLLLLLLLLLLLL",
      "LLLLLLLLLLLLLLLL",
      "LLLLLLLLLLLLLLLL",
      "LLLLLLLLLLLLLLLL",
      "LLLLLLLLLLLLLLLL",
      "LLLLLLLLLLLLLLLL",
      "LLLLLLLLLLLLLLLL",
      "LLLLLLLLLLLLLLLL",
      "LLLLLLLLLLLLLLLL",
      "LLLLLLLLLLLLLLLL"
    ]
  ]
}
