{
  "xsize": 16,
  "zsize": 16,
  "refpalette": "wikitest:test",
  "slices": [
    [
      "RRRRRRRRRRRRRRRR",
      "RRRRRRRRRRRRRRRR",
      "RRRRRRRRRRRRRRRR",
      "RRRRRRRRRRRRRRRR",
      "RRRRRRRRRRRRRRRR",
      "RRRRRRRRRRRRRRRR",
      "RRRRRRRRRRRRRRRR",
      "RRRRRRRRRRRRRRRR",
      "RRRRRRRRRRRRRRRR",
      "RRRRRRRRRRRRRRRR",
      "RRRRRRRRRRRRRRRR",
      "RRRRRRRRRRRRRRRR",
      "RRRRRRRRRRRRRRRR",
      "RRRRRRRRRRRRRRRR",
      "RRRRRRRRRRRRRRRR",
      "RRRRRRRRRRRRRRRR"
    ],
    [
      "RRRRRRRRRRRRRRRR",
      "R______________R",
      "R______________R",
      "R______________R",
      "R______________R",
      "R______________R",
      "R______________R",
      "R______________R",
      "R______________R",
      "R______________R",
      "R______________R",
      "R______________R",
      "R______________R",
      "R______________R",
      "R______________R",
      "RRRRRRRRRRRRRRRR"
    ],
    [
      "RRRRRRRRRRRRRRRR",
      "R______________R",
      "R______________R",
      "R______________R",
      "R______________R",
      "R______________R",
      "R______________R",
      "R______________R",
      "R______________R",
      "R______________R",
      "R______________R",
      "R______________R",
      "R______________R",
      "R______________R",
      "R______________R",
      "RRRRRRRRRRRRRRRR"
    ],
    [
      "RRRRRRRRRRRRRRRR",
      "R______________R",
      "R______________R",
      "R______________R",
      "R______________R",
      "R______________R",
      "R______________R",
      "R______________R",
      "R______________R",
      "R______________R",
      "R______________R",
      "R______________R",
      "R______________R",
      "R______________R",
      "R______________R",
      "RRRRRRRRRRRRRRRR"
    ],
    [
      "RRRRRRRRRRRRRRRR",
      "R______________R",
      "R______________R",
      "R______________R",
      "R______________R",
      "R______________R",
      "R______________R",
      "R______________R",
      "R______________R",
      "R______________R",
      "R______________R",
      "R______________R",
      "R______________R",
      "R______________R",
      "R______________R",
      "RRRRRRRRRRRRRRRR"
    ],
    [
      "RRRRRRRRRRRRRRRR",
      "RRRRRRRRRRRRRRRR",
      "RRRRRRRRRRRRRRRR",
      "RRRRRRRRRRRRRRRR",
      "RRRRRRRRRRRRRRRR",
      "RRRRRRRRRRRRRRRR",
      "RRRRRRRRRRRRRRRR",
      "RRRRRRRRRRRRRRRR",
      "RRRRRRRRRRRRRRRR",
      "RRRRRRRRRRRRRRRR",
      "RRRRRRRRRRRRRRRR",
      "RRRRRRRRRRRRRRRR",
      "RRRRRRRRRRRRRRRR",
      "RRRRRRRRRRRRRRRR",
      "RRRRRRRRRRRRRRRR",
      "RRRRRRRRRRRRRRRR"
    ]
  ]
}
