{
  "xsize": 16,
  "zsize": 16,
  "refpalette": "wikitest:test",
  "slices": [
    [
      "YYYYYYYYYYYYYYYY",
      "YYYYYYYYYYYYYYYY",
      "YYYYYYYYYYYYYYYY",
      "YYYYYYYYYYYYYYYY",
      "YYYYYYYYYYYYYYYY",
      "YYYYYYYYYYYYYYYY",
      "YYYYYYYYYYYYYYYY",
      "YYYYYYYYYYYYYYYY",
      "YYYYYYYYYYYYYYYY",
      "YYYYYYYYYYYYYYYY",
      "YYYYYYYYYYYYYYYY",
      "YYYYYYYYYYYYYYYY",
      "YYYYYYYYYYYYYYYY",
      "YYYYYYYYYYYYYYYY",
      "YYYYYYYYYYYYYYYY",
      "YYYYYYYYYYYYYYYY"
    ],
    [
      "YYYYYYYYYYYYYYYY",
      "Y______________Y",
      "Y______________Y",
      "Y______________Y",
      "Y______________Y",
      "Y______________Y",
      "Y______________Y",
      "Y______________Y",
      "Y______________Y",
      "Y______________Y",
      "Y______________Y",
      "Y______________Y",
      "Y______________Y",
      "Y______________Y",
      "Y______________Y",
      "YYYYYYYYYYYYYYYY"
    ],
    [
      "YYYYYYYYYYYYYYYY",
      "Y______________Y",
      "Y______________Y",
      "Y______________Y",
      "Y______________Y",
      "Y______________Y",
      "Y______________Y",
      "Y______________Y",
      "Y______________Y",
      "Y______________Y",
      "Y______________Y",
      "Y______________Y",
      "Y______________Y",
      "Y______________Y",
      "Y______________Y",
      "YYYYYYYYYYYYYYYY"
    ],
    [
      "YYYYYYYYYYYYYYYY",
      "Y______________Y",
      "Y______________Y",
      "Y______________Y",
      "Y______________Y",
      "Y______________Y",
      "Y______________Y",
      "Y______________Y",
      "Y______________Y",
      "Y______________Y",
      "Y______________Y",
      "Y______________Y",
      "Y______________Y",
      "Y______________Y",
      "Y______________Y",
      "YYYYYYYYYYYYYYYY"
    ],
    [
      "YYYYYYYYYYYYYYYY",
      "Y______________Y",
      "Y______________Y",
      "Y______________Y",
      "Y______________Y",
      "Y______________Y",
      "Y______________Y",
      "Y______________Y",
      "Y______________Y",
      "Y______________Y",
      "Y______________Y",
      "Y______________Y",
      "Y______________Y",
      "Y______________Y",
      "Y______________Y",
      "YYYYYYYYYYYYYYYY"
    ],
    [
      "YYYYYYYYYYYYYYYY",
      "YYYYYYYYYYYYYYYY",
      "YYYYYYYYYYYYYYYY",
      "YYYYYYYYYYYYYYYY",
      "YYYYYYYYYYYYYYYY",
      "YYYYYYYYYYYYYYYY",
      "YYYYYYYYYYYYYYYY",
      "YYYYYYYYYYYYYYYY",
      "YYYYYYYYYYYYYYYY",
      "YYYYYYYYYYYYYYYY",
      "YYYYYYYYYYYYYYYY",
      "YYYYYYYYYYYYYYYY",
      "YYYYYYYYYYYYYYYY",
      "YYYYYYYYYYYYYYYY",
      "YYYYYYYYYYYYYYYY",
      "YYYYYYYYYYYYYYYY"
    ]
  ]
}
