{
  "xsize": 16,
  "zsize": 16,
  "refpalette": "wikitest:test",
  "slices": [
    [
      "NNNNNNNNNNNNNNNN",
      "NNNNNNNNNNNNNNNN",
      "NNNNNNNNNNNNNNNN",
      "NNNNNNNNNNNNNNNN",
      "NNNNNNNNNNNNNNNN",
      "NNNNNNNNNNNNNNNN",
      "NNNNNNNNNNNNNNNN",
      "NNNNNNNNNNNNNNNN",
      "NNNNNNNNNNNNNNNN",
      "NNNNNNNNNNNNNNNN",
      "NNNNNNNNNNNNNNNN",
      "NNNNNNNNNNNNNNNN",
      "NNNNNNNNNNNNNNNN",
      "NNNNNNNNNNNNNNNN",
      "NNNNNNNNNNNNNNNN",
      "NNNNNNNNNNNNNNNN"
    ],
    [
      "NNNNNNNNNNNNNNNN",
      "N______________N",
      "N______________N",
      "N______________N",
      "N______________N",
      "N______________N",
      "N______________N",
      "N______________N",
      "N______________N",
      "N______________N",
      "N______________N",
      "N______________N",
      "N______________N",
      "N______________N",
      "N______________N",
      "NNNNNNNNNNNNNNNN"
    ],
    [
      "NNNNNNNNNNNNNNNN",
      "N______________N",
      "N______________N",
      "N______________N",
      "N______________N",
      "N______________N",
      "N______________N",
      "N______________N",
      "N______________N",
      "N______________N",
      "N______________N",
      "N______________N",
      "N______________N",
      "N______________N",
      "N______________N",
      "NNNNNNNNNNNNNNNN"
    ],
    [
      "NNNNNNNNNNNNNNNN",
      "N______________N",
      "N______________N",
      "N______________N",
      "N______________N",
      "N______________N",
      "N______________N",
      "N______________N",
      "N______________N",
      "N______________N",
      "N______________N",
      "N______________N",
      "N______________N",
      "N______________N",
      "N______________N",
      "NNNNNNNNNNNNNNNN"
    ],
    [
      "NNNNNNNNNNNNNNNN",
      "N______________N",
      "N______________N",
      "N______________N",
      "N______________N",
      "N______________N",
      "N______________N",
      "N______________N",
      "N______________N",
      "N______________N",
      "N______________N",
      "N______________N",
      "N______________N",
      "N______________N",
      "N______________N",
      "NNNNNNNNNNNNNNNN"
    ],
    [
      "NNNNNNNNNNNNNNNN",
      "NNNNNNNNNNNNNNNN",
      "NNNNNNNNNNNNNNNN",
      "NNNNNNNNNNNNNNNN",
      "NNNNNNNNNNNNNNNN",
      "NNNNNNNNNNNNNNNN",
      "NNNNNNNNNNNNNNNN",
      "NNNNNNNNNNNNNNNN",
      "NNNNNNNNNNNNNNNN",
      "NNNNNNNNNNNNNNNN",
      "NNNNNNNNNNNNNNNN",
      "NNNNNNNNNNNNNNNN",
      "NNNNNNNNNNNNNNNN",
      "NNNNNNNNNNNNNNNN",
      "NNNNNNNNNNNNNNNN",
      "NNNNNNNNNNNNNNNN"
    ]
  ]
}
