{
  "xsize": 16,
  "zsize": 16,
  "refpalette": "wikitest:test",
  "slices": [
    [
      "MMMMMMMMMMMMMMMM",
      "MMMMMMMMMMMMMMMM",
      "MMMMMMMMMMMMMMMM",
      "MMMMMMMMMMMMMMMM",
      "MMMMMMMMMMMMMMMM",
      "MMMMMMMMMMMMMMMM",
      "MMMMMMMMMMMMMMMM",
      "MMMMMMMMMMMMMMMM",
      "MMMMMMMMMMMMMMMM",
      "MMMMMMMMMMMMMMMM",
      "MMMMMMMMMMMMMMMM",
      "MMMMMMMMMMMMMMMM",
      "MMMMMMMMMMMMMMMM",
      "MMMMMMMMMMMMMMMM",
      "MMMMMMMMMMMMMMMM",
      "MMMMMMMMMMMMMMMM"
    ],
    [
      "AAAAAAAAAAAAAAAA",
      "A______________A",
      "A______________A",
      "A______________A",
      "A______________A",
      "A______________A",
      "A______________A",
      "A______________A",
      "A______________A",
      "A______________A",
      "A______________A",
      "A______________A",
      "A______________A",
      "A______________A",
      "A______________A",
      "AAAAAAAAAAAAAAAA"
    ],
    [
      "AAAAAAAAAAAAAAAA",
      "A______________A",
      "A______________A",
      "A______________A",
      "A______________A",
      "A______________A",
      "A______________A",
      "A______________A",
      "A______________A",
      "A______________A",
      "A______________A",
      "A______________A",
      "A______________A",
      "A______________A",
      "A______________A",
      "AAAAAAAAAAAAAAAA"
    ],
    [
      "AAAAAAAAAAAAAAAA",
      "A______________A",
      "A______________A",
      "A______________A",
      "A______________A",
      "A______________A",
      "A______________A",
      "A______________A",
      "A______________A",
      "A______________A",
      "A______________A",
      "A______________A",
      "A______________A",
      "A______________A",
      "A______________A",
      "AAAAAAAAAAAAAAAA"
    ],
    [
      "AAAAAAAAAAAAAAAA",
      "A______________A",
      "A______________A",
      "A______________A",
      "A______________A",
      "A______________A",
      "A______________A",
      "A______________A",
      "A______________A",
      "A______________A",
      "A______________A",
      "A______________A",
      "A______________A",
      "A______________A",
      "A______________A",
      "AAAAAAAAAAAAAAAA"
    ],
    [
      "MMMMMMMMMMMMMMMM",
      "MMMMMMMMMMMMMMMM",
      "MMMMMMMMMMMMMMMM",
      "MMMMMMMMMMMMMMMM",
      "MMMMMMMMMMMMMMMM",
      "MMMMMMMMMMMMMMMM",
      "MMMMMMMMMMMMMMMM",
      "MMMMMMMMMMMMMMMM",
      "MMMMMMMMMMMMMMMM",
      "MMMMMMMMMMMMMMMM",
      "MMMMMMMMMMMMMMMM",
      "MMMMMMMMMMMMMMMM",
      "MMMMMMMMMMMMMMMM",
      "MMMMMMMMMMMMMMMM",
      "MMMMMMMMMMMMMMMM",
      "MMMMMMMMMMMMMMMM"
    ]
  ]
}
