{
  "xsize": 16,
  "zsize": 16,
  "refpalette": "wikitest:test",
  "slices": [
    [
      "MMMMMMMMMMMMMMMM",
      "MMMMMMMMMMMMMMMM",
      "MMMMMMMMMMMMMMMM",
      "MMMMMMMMMMMMMMMM",
      "MMMMMMMMMMMMMMMM",
      "MMMMMMMMMMMMMMMM",
      "MMMMMMMMMMMMMMMM",
      "MMMMMMMMMMMMMMMM",
      "MMMMMMMMMMMMMMMM",
      "MMMMMMMMMMMMMMMM",
      "MMMMMMMMMMMMMMMM",
      "MMMMMMMMMMMMMMMM",
      "MMMMMMMMMMMMMMMM",
      "MMMMMMMMMMMMMMMM",
      "MMMMMMMMMMMMMMMM",
      "MMMMMMMMMMMMMMMM"
    ],
    [
      "λλλλλλλλλλλλλλλλ",
      "λ______________λ",
      "λ______________λ",
      "λ______________λ",
      "λ______________λ",
      "λ______________λ",
      "λ______________λ",
      "λ______________λ",
      "λ______________λ",
      "λ______________λ",
      "λ______________λ",
      "λ______________λ",
      "λ______________λ",
      "λ______________λ",
      "λ______________λ",
      "λλλλλλλλλλλλλλλλ"
    ],
    [
      "λλλλλλλλλλλλλλλλ",
      "λ______________λ",
      "λ______________λ",
      "λ______________λ",
      "λ______________λ",
      "λ______________λ",
      "λ______________λ",
      "λ______________λ",
      "λ______________λ",
      "λ______________λ",
      "λ______________λ",
      "λ______________λ",
      "λ______________λ",
      "λ______________λ",
      "λ______________λ",
      "λλλλλλλλλλλλλλλλ"
    ],
    [
      "λλλλλλλλλλλλλλλλ",
      "λ______________λ",
      "λ______________λ",
      "λ______________λ",
      "λ______________λ",
      "λ______________λ",
      "λ______________λ",
      "λ______________λ",
      "λ______________λ",
      "λ______________λ",
      "λ______________λ",
      "λ______________λ",
      "λ______________λ",
      "λ______________λ",
      "λ______________λ",
      "λλλλλλλλλλλλλλλλ"
    ],
    [
      "λλλλλλλλλλλλλλλλ",
      "λ______________λ",
      "λ______________λ",
      "λ______________λ",
      "λ______________λ",
      "λ______________λ",
      "λ______________λ",
      "λ______________λ",
      "λ______________λ",
      "λ______________λ",
      "λ______________λ",
      "λ______________λ",
      "λ______________λ",
      "λ______________λ",
      "λ______________λ",
      "λλλλλλλλλλλλλλλλ"
    ],
    [
      "MMMMMMMMMMMMMMMM",
      "MMMMMMMMMMMMMMMM",
      "MMMMMMMMMMMMMMMM",
      "MMMMMMMMMMMMMMMM",
      "MMMMMMMMMMMMMMMM",
      "MMMMMMMMMMMMMMMM",
      "MMMMMMMMMMMMMMMM",
      "MMMMMMMMMMMMMMMM",
      "MMMMMMMMMMMMMMMM",
      "MMMMMMMMMMMMMMMM",
      "MMMMMMMMMMMMMMMM",
      "MMMMMMMMMMMMMMMM",
      "MMMMMMMMMMMMMMMM",
      "MMMMMMMMMMMMMMMM",
      "MMMMMMMMMMMMMMMM",
      "MMMMMMMMMMMMMMMM"
    ]
  ]
}
