{
  "xsize": 16,
  "zsize": 16,
  "refpalette": "j5:demo",
  "slices": [
    [
      "WWWWWWWWWWWWWWWW",
      "WWWWWWWWWWWWWWWW",
      "WWWWWWWWWWWWWWWW",
      "WWWWWWWWWWWWWWWW",
      "WWWWWWWWWWWWWWWW",
      "WWWWWWWWWWWWWWWW",
      "WWWWWWWWWWWWWWWW",
      "WWWWWWWWWWWWWWWW",
      "WWWWWWWWWWWWWWWW",
      "WWWWWWWWWWWWWWWW",
      "WWWWWWWWWWWWWWWW",
      "WWWWWWWWWWWWWWWW",
      "WWWWWWWWWWWWWWWW",
      "WWWWWWWWWWWWWWWW",
      "WWWWWWWWWWWWWWWW",
      "WWWWWWWWWWWWWWWW"
    ],
    [
      "WWWWWWWWWWWWWWWW",
      "W______________W",
      "W______________W",
      "W______________W",
      "W______________W",
      "W______________W",
      "W______________W",
      "W______________W",
      "W______________W",
      "W______________W",
      "W______________W",
      "W______________W",
      "W______________W",
      "W______________W",
      "W______________W",
      "WWWWWWWWWWWWWWWW"
    ],
    [
      "WWWWWWWWWWWWWWWW",
      "W______________W",
      "W______________W",
      "W______________W",
      "W______________W",
      "W______________W",
      "W______________W",
      "W______________W",
      "W______________W",
      "W______________W",
      "W______________W",
      "W______________W",
      "W______________W",
      "W______________W",
      "W______________W",
      "WWWWWWWWWWWWWWWW"
    ],
    [
      "WWWWWWWWWWWWWWWW",
      "W______________W",
      "W______________W",
      "W______________W",
      "W______________W",
      "W______________W",
      "W______________W",
      "W______________W",
      "W______________W",
      "W______________W",
      "W______________W",
      "W______________W",
      "W______________W",
      "W______________W",
      "W______________W",
      "WWWWWWWWWWWWWWWW"
    ],
    [
      "WWWWWWWWWWWWWWWW",
      "W______________W",
      "W______________W",
      "W______________W",
      "W______________W",
      "W______________W",
      "W______________W",
      "W______________W",
      "W______________W",
      "W______________W",
      "W______________W",
      "W______________W",
      "W______________W",
      "W______________W",
      "W______________W",
      "WWWWWWWWWWWWWWWW"
    ],
    [
      "WWWWWWWWWWWWWWWW",
      "W______________W",
      "W______________W",
      "W______________W",
      "W______________W",
      "W______________W",
      "W______________W",
      "W______________W",
      "W______________W",
      "W______________W",
      "W______________W",
      "W______________W",
      "W______________W",
      "W______________W",
      "W______________W",
      "WWWWWWWWWWWWWWWW"
    ]
  ]
}
