{
  "xsize": 16,
  "zsize": 16,
  "refpalette": "wt9:test",
  "slices": [
    [
      "DDDDDDDDDDDDDDDD",
      "DDDDDDDDDDDDDDDD",
      "DDDDDDDDDDDDDDDD",
      "DDDDDDDDDDDDDDDD",
      "DDDDDDDDDDDDDDDD",
      "DDDDDDDDDDDDDDDD",
      "DDDDDDDDDDDDDDDD",
      "DDDDDDDDDDDDDDDD",
      "DDDDDDDDDDDDDDDD",
      "DDDDDDDDDDDDDDDD",
      "DDDDDDDDDDDDDDDD",
      "DDDDDDDDDDDDDDDD",
      "DDDDDDDDDDDDDDDD",
      "DDDDDDDDDDDDDDDD",
      "DDDDDDDDDDDDDDDD",
      "DDDDDDDDDDDDDDDD"
    ],
    [
      "________________",
      "________________",
      "________________",
      "________________",
      "________________",
      "________________",
      "________________",
      "________________",
      "________________",
      "________________",
      "________________",
      "________________",
      "________________",
      "________________",
      "________________",
      "________________"
    ],
    [
      "________________",
      "________________",
      "________________",
      "________________",
      "________________",
      "________________",
      "________________",
      "________________",
      "________________",
      "________________",
      "________________",
      "________________",
      "________________",
      "________________",
      "________________",
      "________________"
    ],
    [
      "________________",
      "________________",
      "________________",
      "________________",
      "________________",
      "________________",
      "________________",
      "________________",
      "________________",
      "________________",
      "________________",
      "________________",
      "________________",
      "________________",
      "________________",
      "________________"
    ],
    [
      "________________",
      "________________",
      "________________",
      "________________",
      "________________",
      "________________",
      "________________",
      "________________",
      "________________",
      "________________",
      "________________",
      "________________",
      "________________",
      "________________",
      "________________",
      "________________"
    ],
    [
      "________________",
      "________________",
      "________________",
      "________________",
      "________________",
      "________________",
      "________________",
      "________________",
      "________________",
      "________________",
      "________________",
      "________________",
      "________________",
      "________________",
      "________________",
      "________________"
    ]
  ]
}
