{
  "xsize": 16,
  "zsize": 16,
  "refpalette": "wt9:test",
  "slices": [
    [
      "EEEEEEEEEEEEEEEE",
      "EEEEEEEEEEEEEEEE",
      "EEEEEEEEEEEEEEEE",
      "EEEEEEEEEEEEEEEE",
      "EEEEEEEEEEEEEEEE",
      "EEEEEEEEEEEEEEEE",
      "EEEEEEEEEEEEEEEE",
      "EEEEEEEEEEEEEEEE",
      "EEEEEEEEEEEEEEEE",
      "EEEEEEEEEEEEEEEE",
      "EEEEEEEEEEEEEEEE",
      "EEEEEEEEEEEEEEEE",
      "EEEEEEEEEEEEEEEE",
      "EEEEEEEEEEEEEEEE",
      "EEEEEEEEEEEEEEEE",
      "EEEEEEEEEEEEEEEE"
    ],
    [
      "________________",
      "________________",
      "________________",
      "________________",
      "________________",
      "________________",
      "________________",
      "________________",
      "________________",
      "________________",
      "________________",
      "________________",
      "________________",
      "________________",
      "________________",
      "________________"
    ],
    [
      "________________",
      "________________",
      "________________",
      "________________",
      "________________",
      "________________",
      "________________",
      "________________",
      "________________",
      "________________",
      "________________",
      "________________",
      "________________",
      "________________",
      "________________",
      "________________"
    ],
    [
      "________________",
      "________________",
      "________________",
      "________________",
      "________________",
      "________________",
      "________________",
      "________________",
      "________________",
      "________________",
      "________________",
      "________________",
      "________________",
      "________________",
      "________________",
      "________________"
    ],
    [
      "________________",
      "________________",
      "________________",
      "________________",
      "________________",
      "________________",
      "________________",
      "________________",
      "________________",
      "________________",
      "________________",
      "________________",
      "________________",
      "________________",
      "________________",
      "________________"
    ],
    [
      "________________",
      "________________",
      "________________",
      "________________",
      "________________",
      "________________",
      "________________",
      "________________",
      "________________",
      "________________",
      "________________",
      "________________",
      "________________",
      "________________",
      "________________",
      "________________"
    ]
  ]
}
